Workbook

Sheet Cover
A1: Required information E.Info of EN 18031-1
A2: Document name： | B2: RED 18031-1 questionnaire and testing protocol
A3: Version | B3: V1.0
A4: Date | B4: 2025.7.09
A5: Assessed object
A6: Product name
A7: Product Model
A8: Software Version
A9: Developer | B9: SGS Brightsight
A87: UM | B87: QSG
A88: E27527_RT-BE59_UM_EAA | B88: U26937_RT-BE59_folded_EU_QSG_312x450mm_PRINT
A89: Spec
A90: https://www.asus.com/networking-iot-servers/wifi-7/all-series/rt-be59/techspec/

Sheet Interfaces
A1: Interfaces
A2: ID | B2: Name | C2: Category | D2: Sensitive / Confidential / Public (if applicable) | E2: Reference User-Provide Document | F2: Overview | G2: Additional Information
A3: Interface-01 | B3: Wi-Fi Radio (2.4 & 5GHz) | C3: Network interface | D3: Public | E3: ASUS Router HW information in QSG
A4: Interface-02 | B4: LAN Port | C4: Network interface | D4: Public | E4: ASUS Router HW information in QSG | F4: 3 x 1G LAN, 1x2.5G LAN
A5: Interface-03 | B5: WAN Port | C5: Network interface | D5: Public | E5: ASUS Router HW information in QSG | F5: 1 x 2.5G for WAN
A6: Interface-04 | B6: login page | C6: User interface | D6: Sensitive | E6: Web UI screenshot | F6: Local & remote admin portal
A7: Interface-05 | B7: Physical Buttons (Reset / WPS/LED/Power) | C7: User interface | D7: - | E7: ASUS Router HW informatrion in QSG | F7: Tactile control for Wi-Fi, Reset
C8: - | D8: -
C9: - | D9: -
C10: - | D10: -
C11: - | D11: -
C12: - | D12: -
C17: - | D17: -
C18: - | D18: -
C19: - | D19: -
C20: - | D20: -
C21: - | D21: -
C22: - | D22: -
C23: - | D23: -
... C26: - | D26: -

Sheet Generic Network Assets
A1: Network Assets
A2: ID | B2: Name | C2: Category (Network function or Network function configuration) | D2: Sensitive / Confidential / Public (if applicable) | E2: Reference User-Provide Document | F2: Overview | G2: Additional Information
A3: NetworkAsset-01 | B3: WiFi | C3: Network function | D3: Sensitive | E3: [Wireless Router] How to modify Wireless(WiFi) Name and Password in ASUS Router? | Official Support | ASUS Global | F3: This function provides WiFi connectivity. By default, only authorized users can connect using a secure password; however, | G3: Network interface
A4: NetworkAsset-02 | B4: Guest network | C4: Network function | D4: Public | E4: [Wireless Router] How to set up Guest Network on ASUS Router? | Official Support | ASUS Global | F4: A guest network configuration can be enabled to allow access for unauthorized users. | G4: Network interface
A5: NetworkAsset-03 | B5: WiFi configuration | C5: Network configuration | D5: Sensitive | E5: [Wireless Router] How to modify Wireless(WiFi) Name and Password in ASUS Router? | Official Support | ASUS Global | F5: This function provides WiFi connectivity. By default, only authorized users can connect using a secure password; however, a guest network configuration can be enabled to allow access for unauthorized users.
A6: NetworkAsset-04 | B6: LAN(ethernet) | C6: Network function | D6: Sensitive | E6: [Wireless Router] How to change LAN IP of ASUS Wireless Router? | Official Support | ASUS Global | F6: This asset represents the management connection function provided by the AP through the LAN port. It allows administrators to access the AP configuration interface using a local IP to modify settings. | G6: Network interface
A7: NetworkAsset-05 | B7: UPnP function | C7: Network function | D7: Public | E7: [Wireless] How to make my router more secure? | Official Support | ASUS Global | F7: This asset represents the UPnP function available in the management configuration interface. It can be enabled by an administrator to allow additional network discovery or configuration options.
A8: NetworkAsset-06 | B8: UPnP configuration | C8: Network configuration | D8: Sensitive | E8: [Wireless] How to make my router more secure? | Official Support | ASUS Global | F8: This asset represents the UPnP configuration function in the management network configuration interface. It can be enabled by authorized administrators to provide additional network discovery or configuration options.
A9: NetworkAsset-07 | B9: IPv4 settings function | C9: Network function | D9: Public | E9: [Wireless Router] How to set up an Internet Connection?(WAN connection types) | Official Support | ASUS Global | F9: Basic operation of the AP in an IPv4 network. By default, the device operates in DHCP client mode in WAN site and DHCP server in LAN site.
A10: NetworkAsset-08 | B10: IPv4 settings configuration | C10: Network configuration | D10: Sensitive | E10: [Wireless Router] How to set up an Internet Connection?(WAN connection types) | Official Support | ASUS Global | F10: This asset describes the IPv4 configuration of a device.
A11: NetworkAsset-09 | B11: Router SSID | C11: Network configuration | D11: Public | E11: [Wireless Router] How to modify Wireless(WiFi) Name and Password in ASUS Router? | Official Support | ASUS Global
A12: NetworkAsset-10 | B12: Wireless setting configuration | C12: Network configuration | D12: Sensitive | E12: [Wireless Router] How to modify Wireless(WiFi) Name and Password in ASUS Router? | Official Support | ASUS Global
A13: NetworkAsset-11 | B13: Tools function (Ping, Traceroute, NsLookup, Speed Test, LED) | C13: Network function | D13: Sensitive | E13: [Network Tools] How to use Network Analysis(Ping, Traceroute, nslookup) in ASUS Router? | Official Support | ASUS Global | F13: This asset is a preset toolset for trouble shooting, including Ping, WiFi and ethernet packets, Speed ​​Test, LED, etc., and contains some parameters that require users to manually adjust.
A14: NetworkAsset-12 | B14: Tools configuration (Ping, Traceroute, NsLookup, Speed Test, LED) | C14: Network configuration | D14: Sensitive | E14: [Network Tools] How to use Network Analysis(Ping, Traceroute, nslookup) in ASUS Router? | Official Support | ASUS Global
A15: NetworkAsset-13 | B15: Backup/Restore Function | C15: Network function | D15: Sensitive | E15: [Wireless Router] How to upload the configuration files of my ASUS router? | Official Support | ASUS Global | F15: This asset encompasses the backup and restore functionality of the router. It allows network administrators to create secure backups of the devices configuration with password encrypted and system settings, which can be restored in the event of configuration errors, system failures, or during routine maintenance.
A16: NetworkAsset-14 | B16: Backup/Restore Settings | C16: Network configuration | D16: Sensitive | E16: [Wireless Router] How to upload the configuration files of my ASUS router? | Official Support | ASUS Global
A17: NetworkAsset-15 | B17: Syslog function | C17: Network function | D17: Sensitive | E17: [Wireless Router] How to save System Log in my ASUS router? | Official Support | ASUS Global
A18: NetworkAsset-16 | B18: Syslog configuration | C18: Network configuration | D18: Sensitive | E18: [Wireless Router] How to save System Log in my ASUS router? | Official Support | ASUS Global | F18: This asset refers to the syslog functionality of the Access Point. It is designed to collect, store, and forward system logs and event messages generated by the device. The syslog function enables network administrators to monitor system activity, troubleshoot issues, and detect potential security incidents by providing a centralized logging mechanism. It also supports configuration options for directing logs to a remote syslog server and ensuring that critical event data is preserved for analysis and auditing.
A19: NetworkAsset-17 | B19: Traffic Policies (Allow Broadcast/Multicast Traffic, MAC/IP Traffic Filters, Traffic Prioritization ) | C19: Network configuration | D19: Sensitive | E19: [Wireless Router] How to set up IPTV on ASUS router? | Official Support | ASUS Global | F19: Traffic policies manage network flow using MAC/IP filters to allow or block specific traffic, and control broadcast/multicast traffic by allowing you to drop unwanted LAN traffic reaching wireless clients.

Sheet Generic Security Assets
A1: Security Assets
A2: ID | B2: Name | C2: Category (Security function or security parameter) | D2: Sensitive / Confidential / Public | E2: Reference user-provide document | F2: Overview | G2: Additional information
A3: SecurityAsset-01 | B3: AP management websit password authentication | C3: Security function | D3: Confidential | E3: [Wireless Router] How do I enter my ASUS router's setting page using Web GUI? | Official Support | ASUS Global | F3: This asset is primarily used to manage the AP’s WiFi network password authentication mechanism, ensuring that only authorized users can access the AP via its broadcast range and perform system configuration.
A4: SecurityAsset-02 | B4: Access Point User WiFi network password authentication | C4: Security function | D4: Confidential | E4: [Wireless Router] How to modify Wireless(WiFi) Name and Password in ASUS Router? | Official Support | ASUS Global | F4: This password authentication mechanism targets the user WiFi network, allowing only those who enter the correct password to access and use the network.
A5: SecurityAsset-03 | B5: AP user WiFi network password | C5: Security parameter | D5: Confidential | E5: [Wireless Router] How to modify Wireless(WiFi) Name and Password in ASUS Router? | Official Support | ASUS Global | F5: Security parameter for user WiFi networks.
A6: SecurityAsset-04 | B6: AP management websit password | C6: Security parameter | D6: Confidential | E6: [Wireless Router] How do I enter my ASUS router's setting page using Web GUI? | Official Support | ASUS Global | F6: Security parameter for user AP management.
A7: SecurityAsset-05 | B7: AP management websit | C7: Security function | D7: Confidential | E7: [Wireless Router] How do I enter my ASUS router's setting page using Web GUI? | Official Support | ASUS Global | F7: This website is the AP configuration function website, accessible only by authorized administrators for device management and parameter configuration.
A8: SecurityAsset-06 | B8: Firmware Update | C8: Security function | D8: Sensitive | E8: [Wireless Router] How to update the firmware of your router to the latest version ? (WebGUI) | Official Support | ASUS Global | F8: The product supports firmware update management, allowing users to configure the AP via the web interface to automatically or manually download and update firmware versions.
A9: SecurityAsset-07 | B9: WPA2/WPA3 personal function | C9: Security function | D9: Sensitive | E9: [Wireless Router] How to modify Wireless(WiFi) Name and Password in ASUS Router? | Official Support | ASUS Global | F9: This asset refers to the WPA2/WPA3 personal function implemented on the Access Point. It secures wireless communications for user networks by using a pre-shared key (PSK) authentication mechanism.
A10: SecurityAsset-08 | B10: WPA2/WPA3 personal configuration | C10: Security parameter | D10: Sensitive | E10: [Wireless Router] How to modify Wireless(WiFi) Name and Password in ASUS Router? | Official Support | ASUS Global | F10: WPA2/WPA3 personal configuration refers the setting of a secure wireless network using a pre-shared key (PSK) mechanism on the Access Point.
A11: SecurityAsset-09 | B11: WPA2/WPA3 personal passphrase | C11: Security parameter | D11: Confidential | E11: [Wireless Router] How to modify Wireless(WiFi) Name and Password in ASUS Router? | Official Support | ASUS Global | F11: Administrators can set a passphrase for the WiFi network, requiring the password to be between 8 and 63 characters long.
A12: SecurityAsset-10 | B12: WPA2/WPA3 Enterprise function (Radius function) | C12: Security function | D12: Sensitive | E12: [Wireless Router] How to set RADIUS on the wireless of an ASUS router? | Official Support | ASUS Global | F12: The WPA2/WPA3 Enterprise function (RADIUS function) is designed to provide robust, centralized authentication, authorization, and accounting (AAA) for enterprise environments.
A13: SecurityAsset-11 | B13: WPA2/WPA3 Enterprise configuration (Radius) | C13: Security parameter | D13: Sensitive | E13: [Wireless Router] How to set RADIUS on the wireless of an ASUS router? | Official Support | ASUS Global | F13: The configuration process includes entering the RADIUS server’s IP address, port number, and a shared secret that is used to secure the communication between the AP and the RADIUS server.
A14: SecurityAsset-12 | B14: WPA2/WPA3 Enterprise - Radius secret | C14: Security parameter | D14: Confidential | E14: [Wireless Router] How to set RADIUS on the wireless of an ASUS router? | Official Support | ASUS Global | F14: RADIUS secret in WPA2/WPA3 Enterprise configuration is a critical shared secret between the access point and the RADIUS server.
... A17: SecurityAsset-15 | B17: MAC Filter table | C17: Security parameter | D17: Sensitive | E17: [Wireless Router] How to set up Wireless MAC Filter on ASUS Router(WiFi Deny List)? | Official Support | ASUS Global | F17: The MAC Filter table is a component in the MAC Filter configuration on the AP. It stores the list of MAC address entries that determine which devices are allowed or denied network access.
A18: SecurityAsset-16 | B18: DoS protect mechanism | C18: Security function | D18: Confidential | E18: How does DoS protection work? | Official Support | ASUS Global
A19: SecurityAsset-17 | B19: Firewall | C19: Security function | D19: Sensitive | E19: [Wireless Router] Introduction of Firewall on ASUS router | Official Support | ASUS Global | F19: The firewall lets administrators to add custom traffic policies (that is, traffic rules) that apply globally to incoming and outgoing traffic for all WiFi networks. Rules can be added/removed/modified and change priority levels as well.

Sheet TableContent
B2: Note: | C2: The table below lists the requirements of the standard EN18031-1 (column "Requirement") and their respective information to be documented as part of the Technical Documentation (column "Required Information"). The required information can be documented in this template in the respective worksheet (column "Worksheet/tab").
A4: Topic Title | B4: Requirement | C4: Required Information | E4: Worksheet/tab
A5: Access Control Mechanism | B5: ACM-1 | C5: [E.Info.ACM-1.SecurityAsset] | D5: [E.Info.ACM-1.SecurityAsset.Access] | E5: ACM-1.SecAsset
D6: [E.Info.ACM-1.SecurityAsset.PublicAccess]
D7: [E.Info.ACM-1.SecurityAsset.Environment]
D8: [E.Info.ACM-1.SecurityAsset.Legal]
D9: [E.Info.ACM-1.SecurityAsset.ACM]
C10: [E.Info.DT.ACM-1]
C11: [E.Just.DT.ACM-1]
C12: [E.Info.ACM-1.NetworkAsset] | D12: [E.Info.ACM-1.NetworkAsset.Access] | E12: ACM-1.NetAsset
D13: [E.Info.ACM-1.NetworkAsset.PublicAccess]
D14: [E.Info.ACM-1.NetworkAsset.Environment]
D15: [E.Info.ACM-1.NetworkAsset.Legal]
D16: [E.Info.ACM-1.NetworkAsset.ACM]
C17: [E.Info.DT.ACM-1]
C18: [E.Just.DT.ACM-1]
B20: ACM-2 | C20: [E.Info.ACM-2.SecurityAsset] | D20: [E.Info.ACM-2.SecurityAsset.ACM] | E20: ACM-2.SecAsset
C21: [E.Info.DT.ACM-2]
C22: [E.Just.DT.ACM-2]
C23: [E.Info.ACM-2.NetworkAsset] | D23: [E.Info.ACM-2.NetworkAsset.ACM] | E23: ACM-2.NetAsset
C24: [E.Info.DT.ACM-2]
C25: [E.Just.DT.ACM-2]
A27: Authentication Mechanism | B27: AUM-1-1 | C27: [E.Info.AUM-1-1.ACM] | D27: [E.Info.AUM-1-1.ACM.NetworkInterface | E27: AUM-1-1.ACM
D28: [E.Info.AUM-1-1.ACM.ManagedAccessNetworkAsset]
D29: [E.Info.AUM-1-1.ACM.ManagedAccessSecurityAsset]
D30: [E.Info.AUM-1-1.ACM.IntendedFunctionality]
D31: [E.Info.AUM-1-1.ACM.TrustedNetwork]
D32: [E.Info.AUM-1-1.ACM.AuthenticationMechanism]
C33: [E.Info.DT.AUM-1-1]
C34: [E.Just.DT.AUM-1-1]
B35: AUM-1-2 | C35: [E.Info.AUM-1-2.ACM] | D35: [E.Info.AUM-1-2.ACM.UserInterface] | E35: AUM-1-2.ACM
D36: [E.Info.AUM-1-2.ACM.ManagedAccessNetworkAsset]
D37: [E.Info.AUM-1-2.ACM.ManagedAccessSecurityAsset]
D38: [E.Info.AUM-1-2.ACM.IntendedEnvironment]
D39: [E.Info.AUM-1-1.ACM.TrustedNetwork]
D40: [E.Info.AUM-1-2.ACM.AuthenticationMechanism]
C41: [E.Info.DT.AUM-1-2]
C42: [E.Just.DT.AUM-1-2]
B44: AUM-2 | C44: [E.Info.AUM-2.AuthenticationMechanism] | D44: [E.Info.AUM-2.AuthenticationMechanism.AuthFactor] | E44: AUM-2.AUM
C45: [E.Info.DT.AUM-2]
...

Sheet ACM-1.SecAsset
A1: [E.Info.ACM-1.SecurityAsset] | D1: Required information | N1: [E.Info.DT.ACM-1] (Conceptual)
A2: Asset ID | B2: Security Asset name | C2: Description of assets accessible by entities | D2: [E.Info.ACM-1.SecurityAsset.Access] (Nessary) | F2: [E.Info.ACM-1.SecurityAsset.PublicAccess] (conditional) | H2: [E.Info.ACM-1.SecurityAsset.Environment] (Conditional) | J2: [E.Info.ACM-1.SecurityAsset.Legal] (Conditional) | L2: [E.Info.ACM-1.SecurityAsset.ACM] (Conditional) | N2: DT.ACM-1.DN-1 | P2: DT.ACM-1.DN-2 | R2: DT.ACM-1.DN-3 | T2: DT.ACM-1.DN-4
C3: The entities to consider are defined in EN18031-1 as "user, device, equipment or service". For users, it can be useful to document also the role (e.g. privileged/administrator user) | D3: possible entities’ accesses to the security asset on the equipment | F3: (if access control by the equipment is absent for public accessibility of the security asset is the equipment’s intended functionality) Description of the equipment’s intended functionality concerning the public accessibility of the security asset | H3: (if access control by the equipment is absent because physical or logical measures in the equipment’s targeted operational environment exist, that limit accessibility to authorized entities) Description of: o physical or logical access control measures in the equipment’s targeted operational environment; and o how entities are authenticated/authorized in the equipment’s targeted operational environment | J3: (if legal implications do not allow for access control mechanisms) References to all corresponding paragraph(s) or passages in all relevant legal documents, including a description on how this is applicable for the equipment or affected asset | L3: (if access control mechanisms are claimed to be required for entities access to the security asset) Description of each access control mechanism that manages entities’ access to the security asset. | N3: Is the public accessibility of the asset the equipment's intended equipment functionality? | P3: Do the physical or logical measures in the targeted operational environment limit the accessability to authorized entites? | R3: Do legal implications not allow access control mechanisms? | T3: Are there access control mechanisms that manage entities'access to the security assets and network assets ?
D4: Does this item exist? | E4: Reference evidence. | F4: Does this item exist? | G4: Reference evidence. | H4: Does this item exist? | I4: Reference evidence. | J4: Does this item exist? | K4: Reference evidence. | L4: Does this item exist? | M4: Reference evidence. | N4: Decision. | O4: Reference evidence. | P4: Decision. | Q4: Reference evidence. | R4: Decision. | S4: Reference evidence. | T4: Decision. | U4: Reference evidence. | V4: SGS Verdict
A5: SecurityAsset-01 | B5: AP management websit password authentication | C5: Follow the overview in Assets list | D5: Yes | E5: [Wireless Router] How do I enter my ASUS router's setting page using Web GUI? | Official Support | ASUS Global | F5: NA | H5: NA | J5: NA | L5: Yes | M5: [Wireless Router] How do I enter my ASUS router's setting page using Web GUI? | Official Support | ASUS Global | N5: No | P5: No | R5: No | T5: Yes | U5: [Wireless Router] How do I enter my ASUS router's setting page using Web GUI? | Official Support | ASUS Global
A6: SecurityAsset-02 | B6: Access Point User WiFi network password authentication | C6: Follow the overview in Assets list | D6: Yes | E6: [Wireless Router] How to modify Wireless(WiFi) Name and Password in ASUS Router? | Official Support | ASUS Global | F6: NA | H6: NA | J6: NA | L6: Yes | M6: [Wireless Router] How to modify Wireless(WiFi) Name and Password in ASUS Router? | Official Support | ASUS Global | N6: No | P6: No | R6: No | T6: Yes | U6: [Wireless Router] How to modify Wireless(WiFi) Name and Password in ASUS Router? | Official Support | ASUS Global
A7: SecurityAsset-03 | B7: AP user WiFi network password | C7: Follow the overview in Assets list | D7: Yes | E7: [Wireless Router] How to modify Wireless(WiFi) Name and Password in ASUS Router? | Official Support | ASUS Global | F7: NA | H7: NA | J7: NA | L7: Yes | M7: [Wireless Router] How to modify Wireless(WiFi) Name and Password in ASUS Router? | Official Support | ASUS Global | N7: No | P7: No | R7: No | T7: Yes | U7: [Wireless Router] How to modify Wireless(WiFi) Name and Password in ASUS Router? | Official Support | ASUS Global
A8: SecurityAsset-04 | B8: AP management websit password | C8: Follow the overview in Assets list | D8: Yes | E8: [Wireless Router] How do I enter my ASUS router's setting page using Web GUI? | Official Support | ASUS Global | F8: NA | H8: NA | J8: NA | L8: Yes | M8: [Wireless Router] How do I enter my ASUS router's setting page using Web GUI? | Official Support | ASUS Global | N8: No | P8: No | R8: No | T8: Yes | U8: [Wireless Router] How do I enter my ASUS router's setting page using Web GUI? | Official Support | ASUS Global
A9: SecurityAsset-05 | B9: AP management websit | C9: Follow the overview in Assets list | D9: Yes | E9: [Wireless Router] How do I enter my ASUS router's setting page using Web GUI? | Official Support | ASUS Global | F9: NA | H9: NA | J9: NA | L9: Yes | M9: [Wireless Router] How do I enter my ASUS router's setting page using Web GUI? | Official Support | ASUS Global | N9: No | P9: No | R9: No | T9: Yes | U9: [Wireless Router] How do I enter my ASUS router's setting page using Web GUI? | Official Support | ASUS Global
A10: SecurityAsset-06 | B10: Firmware Update | C10: Follow the overview in Assets list | D10: Yes | E10: [Wireless Router] How to update the firmware of your router to the latest version ? (WebGUI) | Official Support | ASUS Global | F10: NA | H10: NA | J10: NA | L10: Yes | M10: [Wireless Router] How to update the firmware of your router to the latest version ? (WebGUI) | Official Support | ASUS Global | N10: No | P10: No | R10: No | T10: Yes | U10: [Wireless Router] How to update the firmware of your router to the latest version ? (WebGUI) | Official Support | ASUS Global
A11: SecurityAsset-07 | B11: WPA2/WPA3 personal function | C11: Follow the overview in Assets list | D11: Yes | E11: [Wireless Router] How to modify Wireless(WiFi) Name and Password in ASUS Router? | Official Support | ASUS Global | F11: NA | H11: NA | J11: NA | L11: Yes | M11: [Wireless Router] How to modify Wireless(WiFi) Name and Password in ASUS Router? | Official Support | ASUS Global | N11: No | P11: No | R11: No | T11: Yes | U11: [Wireless Router] How to modify Wireless(WiFi) Name and Password in ASUS Router? | Official Support | ASUS Global
A12: SecurityAsset-08 | B12: WPA2/WPA3 personal configuration | C12: Follow the overview in Assets list | D12: Yes | E12: [Wireless Router] How to modify Wireless(WiFi) Name and Password in ASUS Router? | Official Support | ASUS Global | F12: NA | H12: NA | J12: NA | L12: Yes | M12: [Wireless Router] How to modify Wireless(WiFi) Name and Password in ASUS Router? | Official Support | ASUS Global | N12: No | P12: No | R12: No | T12: Yes | U12: [Wireless Router] How to modify Wireless(WiFi) Name and Password in ASUS Router? | Official Support | ASUS Global
A13: SecurityAsset-09 | B13: WPA2/WPA3 personal passphrase | C13: Follow the overview in Assets list | D13: Yes | E13: [Wireless Router] How to modify Wireless(WiFi) Name and Password in ASUS Router? | Official Support | ASUS Global | F13: NA | H13: NA | J13: NA | L13: Yes | M13: [Wireless Router] How to modify Wireless(WiFi) Name and Password in ASUS Router? | Official Support | ASUS Global | N13: No | P13: No | R13: No | T13: Yes | U13: [Wireless Router] How to modify Wireless(WiFi) Name and Password in ASUS Router? | Official Support | ASUS Global
A14: SecurityAsset-10 | B14: WPA2/WPA3 Enterprise function (Radius function) | C14: Follow the overview in Assets list | D14: Yes | E14: [Wireless Router] How to set RADIUS on the wireless of an ASUS router? | Official Support | ASUS Global | F14: NA | H14: NA | J14: NA | L14: Yes | M14: [Wireless Router] How to set RADIUS on the wireless of an ASUS router? | Official Support | ASUS Global | N14: No | P14: No | R14: No | T14: Yes | U14: [Wireless Router] How to set RADIUS on the wireless of an ASUS router? | Official Support | ASUS Global
A15: SecurityAsset-11 | B15: WPA2/WPA3 Enterprise configuration (Radius) | C15: Follow the overview in Assets list | D15: Yes | E15: [Wireless Router] How to set RADIUS on the wireless of an ASUS router? | Official Support | ASUS Global | F15: NA | H15: NA | J15: NA | L15: Yes | M15: [Wireless Router] How to set RADIUS on the wireless of an ASUS router? | Official Support | ASUS Global | N15: No | P15: No | R15: No | T15: Yes | U15: [Wireless Router] How to set RADIUS on the wireless of an ASUS router? | Official Support | ASUS Global
A16: SecurityAsset-12 | B16: WPA2/WPA3 Enterprise - Radius secret | C16: Follow the overview in Assets list | D16: Yes | E16: [Wireless Router] How to set RADIUS on the wireless of an ASUS router? | Official Support | ASUS Global | F16: NA | H16: NA | J16: NA | L16: Yes | M16: [Wireless Router] How to set RADIUS on the wireless of an ASUS router? | Official Support | ASUS Global | N16: No | P16: No | R16: No | T16: Yes | U16: [Wireless Router] How to set RADIUS on the wireless of an ASUS router? | Official Support | ASUS Global
... A21: SecurityAsset-17 | B21: Global Traffic Filter | C21: Follow the overview in Assets list | D21: Yes | E21: [Wireless Router] Introduction of Firewall on ASUS router | Official Support | ASUS Global | F21: NA | H21: NA | J21: NA | L21: Yes | M21: [Wireless Router] Introduction of Firewall on ASUS router | Official Support | ASUS Global | N21: No | P21: No | R21: No | T21: Yes | U21: [Wireless Router] Introduction of Firewall on ASUS router | Official Support | ASUS Global

Sheet ACM-1.NetAsset
A1: [E.Info.ACM-1.NetworkAsset] | D1: Required information | N1: [E.Info.DT.ACM-1] (Conceptual)
A2: Asset ID | B2: Network Asset name | C2: Description of assets accessible by entities | D2: [E.Info.ACM-1.NetworkAsset.Access] (Nessary) | F2: [E.Info.ACM-1.NetworkAsset.PublicAccess] (conditional) | H2: [E.Info.ACM-1.NetworkAsset.Environment] (Conditional) | J2: [E.Info.ACM-1.NetworkAsset.Legal] (Conditional) | L2: [E.Info.ACM-1.NetworkAsset.ACM] (Conditional) | N2: DT.ACM-1.DN-1 | P2: DT.ACM-1.DN-2 | R2: DT.ACM-1.DN-3 | T2: DT.ACM-1.DN-4
C3: The entities to consider are defined in EN18031-1 as "user, device, equipment or service". For users, it can be useful to document also the role (e.g. privileged/administrator user) | D3: possible entities’ accesses to the network asset on the equipment | F3: (if access control by the equipment is absent for public accessibility of the network asset is the equipment’s intended functionality) Description of the equipment’s intended functionality concerning the public accessibility of the network asset | H3: (if access control by the equipment is absent because physical or logical measures in the equipment’s targeted operational environment exits, that limit accessibility to authorized entities) Description of: o physical or logical access control measures in the equipment’s targeted operational environment; and o how entities are authenticated/authorized in the equipment’s targeted operational environment | J3: (if legal implications do not allow for access control mechanisms) References to all corresponding paragraph(s) or passages in all relevant legal documents, including a description on how this is applicable for the equipment or affected asset | L3: (if access control mechanisms are claimed to be required for entities access to the network asset) Description of each access control mechanism that manages entities’ access to the network asset. | N3: Is the public accessibility of the asset the equipment's intended equipment functionality? | P3: Do the physical or logical measures in the targeted operational environment limit the accessability to authorized entites? | R3: Do legal implications not allow access control mechanisms? | T3: Are there access control mechanisms that manage entities'access to the Network assets?
D4: Does this item exist? | E4: Reference evidence. | F4: Does this item exist? | G4: Reference evidence. | H4: Does this item exist? | I4: Reference evidence. | J4: Does this item exist? | K4: Reference evidence. | L4: Does this item exist? | M4: Reference evidence. | N4: Decision. | O4: Reference evidence. | P4: Decision. | Q4: Reference evidence. | R4: Decision. | S4: Reference evidence. | T4: Decision. | U4: Reference evidence. | V4: SGS Verdict
A5: NetworkAsset-01 | B5: WiFi | C5: Follow the overview in Assist list | D5: Yes | E5: [Wireless Router] How to modify Wireless(WiFi) Name and Password in ASUS Router? | Official Support | ASUS Global | F5: No | H5: No | J5: No | L5: Yes | M5: [Wireless Router] How to modify Wireless(WiFi) Name and Password in ASUS Router? | Official Support | ASUS Global | N5: No | P5: No | R5: No | T5: Yes | U5: [Wireless Router] How to modify Wireless(WiFi) Name and Password in ASUS Router? | Official Support | ASUS Global
A6: NetworkAsset-02 | B6: Guest network | C6: Follow the overview in Assist list | D6: Yes | E6: [Wireless Router] How to set up Guest Network on ASUS Router? | Official Support | ASUS Global | F6: Yes | H6: No | J6: No | N6: Yes | O6: [Wireless Router] How to set up Guest Network on ASUS Router? | Official Support | ASUS Global
A7: NetworkAsset-03 | B7: WiFi configuration | C7: Follow the overview in Assist list | D7: Yes | E7: [Wireless Router] How to modify Wireless(WiFi) Name and Password in ASUS Router? | Official Support | ASUS Global | F7: No | H7: No | J7: No | L7: Yes | M7: [Wireless Router] How to modify Wireless(WiFi) Name and Password in ASUS Router? | Official Support | ASUS Global | N7: No | P7: No | R7: No | T7: Yes | U7: [Wireless Router] How to modify Wireless(WiFi) Name and Password in ASUS Router? | Official Support | ASUS Global
A8: NetworkAsset-04 | B8: LAN(ethernet) | C8: Follow the overview in Assist list | D8: Yes | E8: [Wireless Router] How to change LAN IP of ASUS Wireless Router? | Official Support | ASUS Global | F8: No | H8: Yes | I8: The QSG indicated that the router is for indoor use only. | J8: No | N8: No | P8: Yes | Q8: The QSG indicated that the router is for indoor use only.
A9: NetworkAsset-05 | B9: UPnP function | C9: Follow the overview in Assist list | D9: Yes | E9: [Wireless] How to make my router more secure? | Official Support | ASUS Global | F9: Yes | G9: [Wireless] How to make my router more secure? | Official Support | ASUS Global | H9: Yes | I9: The QSG indicated that the router is for indoor use only. | J9: No | N9: No | P9: Yes | Q9: The QSG indicated that the router is for indoor use only.
A10: NetworkAsset-06 | B10: UPnP configuration | C10: Follow the overview in Assist list | D10: Yes | E10: [Wireless] How to make my router more secure? | Official Support | ASUS Global | F10: No | H10: No | J10: No | L10: Yes | M10: [Wireless] How to make my router more secure? | Official Support | ASUS Global | N10: No | P10: No | R10: No | T10: Yes | U10: [Wireless] How to make my router more secure? | Official Support | ASUS Global
A11: NetworkAsset-07 | B11: IPv4 settings function | C11: Follow the overview in Assist list | D11: Yes | E11: [Wireless Router] How to set up an Internet Connection?(WAN connection types) | Official Support | ASUS Global | F11: Yes | H11: No | J11: No | N11: No | P11: Yes
A12: NetworkAsset-08 | B12: IPv4 settings configuration | C12: Follow the overview in Assist list | D12: Yes | E12: [Wireless Router] How to set up an Internet Connection?(WAN connection types) | Official Support | ASUS Global | F12: No | H12: No | J12: No | L12: Yes | M12: [Wireless Router] How to set up an Internet Connection?(WAN connection types) | Official Support | ASUS Global | N12: No | P12: No | R12: No | T12: Yes | U12: [Wireless Router] How to set up an Internet Connection?(WAN connection types) | Official Support | ASUS Global
A13: NetworkAsset-09 | B13: Router SSID | C13: Follow the overview in Assist list | D13: Yes | E13: [Wireless Router] How to modify Wireless(WiFi) Name and Password in ASUS Router? | Official Support | ASUS Global | F13: Yes | H13: No | J13: No | N13: Yes | O13: [Wireless Router] How to modify Wireless(WiFi) Name and Password in ASUS Router? | Official Support | ASUS Global
A14: NetworkAsset-10 | B14: Wireless setting configuration | C14: Follow the overview in Assist list | D14: Yes | E14: [Wireless Router] How to modify Wireless(WiFi) Name and Password in ASUS Router? | Official Support | ASUS Global | F14: No | H14: No | J14: No | L14: Yes | M14: [Wireless Router] How to modify Wireless(WiFi) Name and Password in ASUS Router? | Official Support | ASUS Global | N14: No | P14: No | R14: No | T14: Yes | U14: [Wireless Router] How to modify Wireless(WiFi) Name and Password in ASUS Router? | Official Support | ASUS Global
A15: NetworkAsset-11 | B15: Tools function (Ping, Traceroute, NsLookup, Speed Test, LED) | C15: Follow the overview in Assist list | D15: Yes | E15: [Network Tools] How to use Network Analysis(Ping, Traceroute, nslookup) in ASUS Router? | Official Support | ASUS Global | F15: No | H15: No | J15: No | L15: Yes | M15: [Network Tools] How to use Network Analysis(Ping, Traceroute, nslookup) in ASUS Router? | Official Support | ASUS Global | N15: No | P15: No | R15: No | T15: Yes | U15: [Network Tools] How to use Network Analysis(Ping, Traceroute, nslookup) in ASUS Router? | Official Support | ASUS Global
A16: NetworkAsset-12 | B16: Tools configuration (Ping, Traceroute, NsLookup, Speed Test, LED) | C16: Follow the overview in Assist list | D16: Yes | E16: [Network Tools] How to use Network Analysis(Ping, Traceroute, nslookup) in ASUS Router? | Official Support | ASUS Global | F16: No | H16: No | J16: No | L16: Yes | M16: [Network Tools] How to use Network Analysis(Ping, Traceroute, nslookup) in ASUS Router? | Official Support | ASUS Global | N16: No | P16: No | R16: No | T16: Yes | U16: [Network Tools] How to use Network Analysis(Ping, Traceroute, nslookup) in ASUS Router? | Official Support | ASUS Global
A17: NetworkAsset-13 | B17: Backup/Restore Function | C17: Follow the overview in Assist list | D17: Yes | E17: [Wireless Router] How to upload the configuration files of my ASUS router? | Official Support | ASUS Global | F17: No | H17: No | J17: No | L17: Yes | M17: [Wireless Router] How to upload the configuration files of my ASUS router? | Official Support | ASUS Global | N17: No | P17: No | R17: No | T17: Yes | U17: [Wireless Router] How to upload the configuration files of my ASUS router? | Official Support | ASUS Global
A18: NetworkAsset-14 | B18: Backup/Restore Settings | C18: Follow the overview in Assist list | D18: Yes | E18: [Wireless Router] How to upload the configuration files of my ASUS router? | Official Support | ASUS Global | F18: No | H18: No | J18: No | L18: Yes | M18: [Wireless Router] How to upload the configuration files of my ASUS router? | Official Support | ASUS Global | N18: No | P18: No | R18: No | T18: Yes | U18: [Wireless Router] How to upload the configuration files of my ASUS router? | Official Support | ASUS Global
A19: NetworkAsset-15 | B19: Syslog function | C19: Follow the overview in Assist list | D19: Yes | E19: [Wireless Router] How to save System Log in my ASUS router? | Official Support | ASUS Global | F19: No | H19: No | J19: No | L19: Yes | M19: [Wireless Router] How to save System Log in my ASUS router? | Official Support | ASUS Global | N19: No | P19: No | R19: No | T19: Yes | U19: [Wireless Router] How to save System Log in my ASUS router? | Official Support | ASUS Global
A20: NetworkAsset-16 | B20: Syslog configuration | C20: Follow the overview in Assist list | D20: Yes | E20: [Wireless Router] How to save System Log in my ASUS router? | Official Support | ASUS Global | F20: No | H20: No | J20: No | L20: Yes | M20: [Wireless Router] How to save System Log in my ASUS router? | Official Support | ASUS Global | N20: No | P20: No | R20: No | T20: Yes | U20: [Wireless Router] How to save System Log in my ASUS router? | Official Support | ASUS Global
A21: NetworkAsset-17 | B21: Traffic Policies (Allow Broadcast/Multicast Traffic, MAC/IP Traffic Filters, Traffic Prioritization ) | C21: Follow the overview in Assist list | D21: Yes | E21: [Wireless Router] How to set up IPTV on ASUS router? | Official Support | ASUS Global | F21: No | H21: No | J21: No | L21: Yes | M21: [Wireless Router] How to set up IPTV on ASUS router? | Official Support | ASUS Global | N21: No | P21: No | R21: No | T21: Yes | U21: [Wireless Router] How to set up IPTV on ASUS router? | Official Support | ASUS Global

Sheet ACM-2.SecAsset
A1: [E.Info.ACM-2.SecurityAsset] | E1: Required information | O1: Conceptual
A2: Asset ID | B2: Security Asset name | C2: Description of assets requiring access control | D2: Implementation categories (IC) | E2: [E.Info.ACM-2.SecurityAsset.ACM] | G2: [IC.ACM-2.RBAC] | I2: [IC.ACM-2.DAC] | K2: [IC.ACM-2.MAC] | M2: [IC.ACM-2.Generic] | O2: [E.Info.ACM-2.SecurityAsset] (Conceptual)
C3: Report the security assets from the worksheet ACM-1.SecAsset where DT.ACM-1.DN-4 is Yes | D3: [IC.ACM-2.RBAC] [IC.ACM-2.DAC] [IC.ACM-2.MAC] [IC.ACM-2.Generic] | E3: Description of each access control mechanism required per ACM-1 that manages entities' access to the security asset and of how the mechanisms ensure that only authorized entities have access to the security asset based on the implementation category. | G3: The methods to validate the appropriateness of the access control mechanism solely rely on role-based access control. | I3: The methods to validate the appropriateness of the access control mechanism solely rely on discretionary access control. | K3: The methods to validate the appropriateness of the access control mechanism solely rely on mandatory access control. | M3: The methods to validate the appropriateness of the access control mechanism do not solely rely on any of the methods described in ACM-2-RBAC, ACM-2-DAC or ACM-2-MAC. | O3: Do the access control mechanisms ensure that only authorized entities have access to the protected security and network asset?
E4: Does this item exist? | F4: Reference evidence. | G4: Does this item exist? | H4: Reference evidence. | I4: Does this item exist? | J4: Reference evidence. | K4: Does this item exist? | L4: Reference evidence. | M4: Does this item exist? | N4: Reference evidence. | O4: Decision. | P4: Reference evidence. | Q4: SGS Verdict
A5: SecurityAsset-01 | B5: AP management websit password authentication | C5: Follow the overview in Assest List previously | D5: [IC.ACM-2.Generic] | E5: Yes | F5: [Wireless Router] How do I enter my ASUS router's setting page using Web GUI? | Official Support | ASUS Global | G5: NA | I5: NA | K5: NA | M5: Yes | N5: [Wireless Router] How do I enter my ASUS router's setting page using Web GUI? | Official Support | ASUS Global | O5: Yes | P5: [Wireless Router] How do I enter my ASUS router's setting page using Web GUI? | Official Support | ASUS Global
A6: SecurityAsset-02 | B6: Access Point User WiFi network password authentication | C6: Follow the overview in Assest List previously | D6: [IC.ACM-2.Generic] | E6: Yes | F6: [Wireless Router] How to modify Wireless(WiFi) Name and Password in ASUS Router? | Official Support | ASUS Global | G6: NA | I6: NA | K6: NA | M6: Yes | N6: [Wireless Router] How to modify Wireless(WiFi) Name and Password in ASUS Router? | Official Support | ASUS Global | O6: Yes | P6: [Wireless Router] How to modify Wireless(WiFi) Name and Password in ASUS Router? | Official Support | ASUS Global
A7: SecurityAsset-03 | B7: AP user WiFi network password | C7: Follow the overview in Assest List previously | D7: [IC.ACM-2.Generic] | E7: Yes | F7: [Wireless Router] How to modify Wireless(WiFi) Name and Password in ASUS Router? | Official Support | ASUS Global | G7: NA | I7: NA | K7: NA | M7: Yes | N7: [Wireless Router] How to modify Wireless(WiFi) Name and Password in ASUS Router? | Official Support | ASUS Global | O7: Yes | P7: [Wireless Router] How to modify Wireless(WiFi) Name and Password in ASUS Router? | Official Support | ASUS Global
A8: SecurityAsset-04 | B8: AP management websit password | C8: Follow the overview in Assest List previously | D8: [IC.ACM-2.Generic] | E8: Yes | F8: [Wireless Router] How do I enter my ASUS router's setting page using Web GUI? | Official Support | ASUS Global | G8: NA | I8: NA | K8: NA | M8: Yes | N8: [Wireless Router] How do I enter my ASUS router's setting page using Web GUI? | Official Support | ASUS Global | O8: Yes | P8: [Wireless Router] How do I enter my ASUS router's setting page using Web GUI? | Official Support | ASUS Global
A9: SecurityAsset-05 | B9: AP management websit | C9: Follow the overview in Assest List previously | D9: [IC.ACM-2.Generic] | E9: Yes | F9: [Wireless Router] How do I enter my ASUS router's setting page using Web GUI? | Official Support | ASUS Global | G9: NA | I9: NA | K9: NA | M9: Yes | N9: [Wireless Router] How do I enter my ASUS router's setting page using Web GUI? | Official Support | ASUS Global | O9: Yes | P9: [Wireless Router] How do I enter my ASUS router's setting page using Web GUI? | Official Support | ASUS Global
A10: SecurityAsset-06 | B10: Firmware Update | C10: Follow the overview in Assest List previously | D10: [IC.ACM-2.Generic] | E10: Yes | F10: [Wireless Router] How to update the firmware of your router to the latest version ? (WebGUI) | Official Support | ASUS Global | G10: NA | I10: NA | K10: NA | M10: Yes | N10: [Wireless Router] How to update the firmware of your router to the latest version ? (WebGUI) | Official Support | ASUS Global | O10: Yes | P10: [Wireless Router] How to update the firmware of your router to the latest version ? (WebGUI) | Official Support | ASUS Global
A11: SecurityAsset-07 | B11: WPA2/WPA3 personal function | C11: Follow the overview in Assest List previously | D11: [IC.ACM-2.Generic] | E11: Yes | F11: [Wireless Router] How to modify Wireless(WiFi) Name and Password in ASUS Router? | Official Support | ASUS Global | G11: NA | I11: NA | K11: NA | M11: Yes | N11: [Wireless Router] How to modify Wireless(WiFi) Name and Password in ASUS Router? | Official Support | ASUS Global | O11: Yes | P11: [Wireless Router] How to modify Wireless(WiFi) Name and Password in ASUS Router? | Official Support | ASUS Global
A12: SecurityAsset-08 | B12: WPA2/WPA3 personal configuration | C12: Follow the overview in Assest List previously | D12: [IC.ACM-2.Generic] | E12: Yes | F12: [Wireless Router] How to modify Wireless(WiFi) Name and Password in ASUS Router? | Official Support | ASUS Global | G12: NA | I12: NA | K12: NA | M12: Yes | N12: [Wireless Router] How to modify Wireless(WiFi) Name and Password in ASUS Router? | Official Support | ASUS Global | O12: Yes | P12: [Wireless Router] How to modify Wireless(WiFi) Name and Password in ASUS Router? | Official Support | ASUS Global
A13: SecurityAsset-09 | B13: WPA2/WPA3 personal passphrase | C13: Follow the overview in Assest List previously | D13: [IC.ACM-2.Generic] | E13: Yes | F13: [Wireless Router] How to modify Wireless(WiFi) Name and Password in ASUS Router? | Official Support | ASUS Global | G13: NA | I13: NA | K13: NA | M13: Yes | N13: [Wireless Router] How to modify Wireless(WiFi) Name and Password in ASUS Router? | Official Support | ASUS Global | O13: Yes | P13: [Wireless Router] How to modify Wireless(WiFi) Name and Password in ASUS Router? | Official Support | ASUS Global
A14: SecurityAsset-10 | B14: WPA2/WPA3 Enterprise function (Radius function) | C14: Follow the overview in Assest List previously | D14: [IC.ACM-2.Generic] | E14: Yes | F14: [Wireless Router] How to set RADIUS on the wireless of an ASUS router? | Official Support | ASUS Global | G14: NA | I14: NA | K14: NA | M14: Yes | N14: [Wireless Router] How to set RADIUS on the wireless of an ASUS router? | Official Support | ASUS Global | O14: Yes | P14: [Wireless Router] How to set RADIUS on the wireless of an ASUS router? | Official Support | ASUS Global
A15: SecurityAsset-11 | B15: WPA2/WPA3 Enterprise configuration (Radius) | C15: Follow the overview in Assest List previously | D15: [IC.ACM-2.Generic] | E15: Yes | F15: [Wireless Router] How to set RADIUS on the wireless of an ASUS router? | Official Support | ASUS Global | G15: NA | I15: NA | K15: NA | M15: Yes | N15: [Wireless Router] How to set RADIUS on the wireless of an ASUS router? | Official Support | ASUS Global | O15: Yes | P15: [Wireless Router] How to set RADIUS on the wireless of an ASUS router? | Official Support | ASUS Global
A16: SecurityAsset-12 | B16: WPA2/WPA3 Enterprise - Radius secret | C16: Follow the overview in Assest List previously | D16: [IC.ACM-2.Generic] | E16: Yes | F16: [Wireless Router] How to set RADIUS on the wireless of an ASUS router? | Official Support | ASUS Global | G16: NA | I16: NA | K16: NA | M16: Yes | N16: [Wireless Router] How to set RADIUS on the wireless of an ASUS router? | Official Support | ASUS Global | O16: Yes | P16: [Wireless Router] How to set RADIUS on the wireless of an ASUS router? | Official Support | ASUS Global
... A21: SecurityAsset-17 | B21: Firewall | C21: Follow the overview in Assest List previously | D21: [IC.ACM-2.Generic] | E21: Yes | F21: [Wireless Router] Introduction of Firewall on ASUS router | Official Support | ASUS Global | G21: NA | I21: NA | K21: NA | M21: Yes | N21: [Wireless Router] Introduction of Firewall on ASUS router | Official Support | ASUS Global | O21: Yes | P21: [Wireless Router] Introduction of Firewall on ASUS router | Official Support | ASUS Global

Sheet ACM-2.NetAsset
A1: [E.Info.ACM-2.NetAsset] | F1: Required information | P1: Conceptual
A2: Asset ID | B2: Network Asset name | C2: Description of assets requiring access control | E2: Implementation categories (IC) | F2: [E.Info.ACM-2.NetworkAsset.ACM] | H2: [IC.ACM-2.RBAC] | J2: [IC.ACM-2.DAC] | L2: [IC.ACM-2.MAC] | N2: [IC.ACM-2.Generic] | P2: [E.Info.ACM-2.NetworkAsset] (Conceptual)
C3: Report the security assets from the worksheet ACM-1.NetAsset where DT.ACM-1.DN-4 is Yes | E3: [IC.ACM-2.RBAC] [IC.ACM-2.DAC] [IC.ACM-2.MAC] [IC.ACM-2.Generic] | F3: Description of each access control mechanism required per ACM-1 that manages entities' access to the network asset and of how the mechanisms ensure that only authorized entities have access to the network asset based on the implementation category. | H3: The methods to validate the appropriateness of the access control mechanism solely rely on role-based access control. | J3: The methods to validate the appropriateness of the access control mechanism solely rely on discretionary access control. | L3: The methods to validate the appropriateness of the access control mechanism solely rely on mandatory access control. | N3: The methods to validate the appropriateness of the access control mechanism do not solely rely on any of the methods described in ACM-2-RBAC, ACM-2-DAC or ACM-2-MAC. | P3: Do the access control mechanisms ensure that only authorized entities have access to the protected security and network asset?
F4: Does this item exist? | G4: Reference evidence. | H4: Does this item exist? | I4: Reference evidence. | J4: Does this item exist? | K4: Reference evidence. | L4: Does this item exist? | M4: Reference evidence. | N4: Does this item exist? | O4: Reference evidence. | P4: Decision. | Q4: Reference evidence. | R4: SGS Verdict
A5: NetworkAsset-01 | B5: WiFi | C5: Follow the overview in Assest List previously | E5: [IC.ACM-2.Generic] | F5: Yes | G5: [Wireless Router] How to modify Wireless(WiFi) Name and Password in ASUS Router? | Official Support | ASUS Global | H5: NA | J5: NA | L5: NA | N5: Yes | O5: [Wireless Router] How to modify Wireless(WiFi) Name and Password in ASUS Router? | Official Support | ASUS Global | P5: Yes | Q5: [Wireless Router] How to modify Wireless(WiFi) Name and Password in ASUS Router? | Official Support | ASUS Global
A6: NetworkAsset-03 | B6: WiFi configuration | C6: Follow the overview in Assest List previously | E6: [IC.ACM-2.Generic] | F6: Yes | G6: [Wireless Router] How to modify Wireless(WiFi) Name and Password in ASUS Router? | Official Support | ASUS Global | H6: NA | J6: NA | L6: NA | N6: Yes | O6: [Wireless Router] How to modify Wireless(WiFi) Name and Password in ASUS Router? | Official Support | ASUS Global | P6: Yes | Q6: [Wireless Router] How to modify Wireless(WiFi) Name and Password in ASUS Router? | Official Support | ASUS Global
A7: NetworkAsset-06 | B7: UPnP configuration | C7: Follow the overview in Assest List previously | E7: [IC.ACM-2.Generic] | F7: Yes | G7: [Wireless] How to make my router more secure? | Official Support | ASUS Global | H7: NA | J7: NA | L7: NA | N7: Yes | O7: [Wireless] How to make my router more secure? | Official Support | ASUS Global | P7: Yes | Q7: [Wireless] How to make my router more secure? | Official Support | ASUS Global
A8: NetworkAsset-08 | B8: IPv4 settings configuration | C8: Follow the overview in Assest List previously | E8: [IC.ACM-2.Generic] | F8: Yes | G8: [Wireless Router] How to set up an Internet Connection?(WAN connection types) | Official Support | ASUS Global | H8: NA | J8: NA | L8: NA | N8: Yes | O8: [Wireless Router] How to set up an Internet Connection?(WAN connection types) | Official Support | ASUS Global | P8: Yes | Q8: [Wireless Router] How to set up an Internet Connection?(WAN connection types) | Official Support | ASUS Global
A9: NetworkAsset-10 | B9: Wireless setting configuration | C9: Follow the overview in Assest List previously | E9: [IC.ACM-2.Generic] | F9: Yes | G9: [Wireless Router] How to modify Wireless(WiFi) Name and Password in ASUS Router? | Official Support | ASUS Global | H9: NA | J9: NA | L9: NA | N9: Yes | O9: [Wireless Router] How to modify Wireless(WiFi) Name and Password in ASUS Router? | Official Support | ASUS Global | P9: Yes | Q9: [Wireless Router] How to modify Wireless(WiFi) Name and Password in ASUS Router? | Official Support | ASUS Global
A10: NetworkAsset-11 | B10: Tools function (Ping, Traceroute, NsLookup, Speed Test, LED) | C10: Follow the overview in Assest List previously | E10: [IC.ACM-2.Generic] | F10: Yes | G10: [Network Tools] How to use Network Analysis(Ping, Traceroute, nslookup) in ASUS Router? | Official Support | ASUS Global | H10: NA | J10: NA | L10: NA | N10: Yes | O10: [Network Tools] How to use Network Analysis(Ping, Traceroute, nslookup) in ASUS Router? | Official Support | ASUS Global | P10: Yes | Q10: [Network Tools] How to use Network Analysis(Ping, Traceroute, nslookup) in ASUS Router? | Official Support | ASUS Global
A11: NetworkAsset-12 | B11: Tools configuration (Ping, Traceroute, NsLookup, Speed Test, LED) | C11: Follow the overview in Assest List previously | E11: [IC.ACM-2.Generic] | F11: Yes | G11: [Network Tools] How to use Network Analysis(Ping, Traceroute, nslookup) in ASUS Router? | Official Support | ASUS Global | H11: NA | J11: NA | L11: NA | N11: Yes | O11: [Network Tools] How to use Network Analysis(Ping, Traceroute, nslookup) in ASUS Router? | Official Support | ASUS Global | P11: Yes | Q11: [Network Tools] How to use Network Analysis(Ping, Traceroute, nslookup) in ASUS Router? | Official Support | ASUS Global
A12: NetworkAsset-13 | B12: Backup/Restore Function | C12: Follow the overview in Assest List previously | E12: [IC.ACM-2.Generic] | F12: Yes | G12: [Wireless Router] How to upload the configuration files of my ASUS router? | Official Support | ASUS Global | H12: NA | J12: NA | L12: NA | N12: Yes | O12: [Wireless Router] How to upload the configuration files of my ASUS router? | Official Support | ASUS Global | P12: Yes | Q12: [Wireless Router] How to upload the configuration files of my ASUS router? | Official Support | ASUS Global
A13: NetworkAsset-14 | B13: Backup/Restore Settings | C13: Follow the overview in Assest List previously | E13: [IC.ACM-2.Generic] | F13: Yes | G13: [Wireless Router] How to upload the configuration files of my ASUS router? | Official Support | ASUS Global | H13: NA | J13: NA | L13: NA | N13: Yes | O13: [Wireless Router] How to upload the configuration files of my ASUS router? | Official Support | ASUS Global | P13: Yes | Q13: [Wireless Router] How to upload the configuration files of my ASUS router? | Official Support | ASUS Global
A14: NetworkAsset-15 | B14: Syslog function | C14: Follow the overview in Assest List previously | E14: [IC.ACM-2.Generic] | F14: Yes | G14: [Wireless Router] How to save System Log in my ASUS router? | Official Support | ASUS Global | H14: NA | J14: NA | L14: NA | N14: Yes | O14: [Wireless Router] How to save System Log in my ASUS router? | Official Support | ASUS Global | P14: Yes | Q14: [Wireless Router] How to save System Log in my ASUS router? | Official Support | ASUS Global
A15: NetworkAsset-16 | B15: Syslog configuration | C15: Follow the overview in Assest List previously | D15: IC.ACM-2.Generic | E15: [IC.ACM-2.Generic] | F15: Yes | G15: [Wireless Router] How to save System Log in my ASUS router? | Official Support | ASUS Global | H15: NA | J15: NA | L15: NA | N15: Yes | O15: [Wireless Router] How to save System Log in my ASUS router? | Official Support | ASUS Global | P15: Yes | Q15: [Wireless Router] How to save System Log in my ASUS router? | Official Support | ASUS Global
A16: NetworkAsset-17 | B16: Traffic Policies (Allow Broadcast/Multicast Traffic, MAC/IP Traffic Filters, Traffic Prioritization ) | C16: Follow the overview in Assest List previously | D16: IC.ACM-2.RBAC | E16: [IC.ACM-2.Generic] | F16: Yes | G16: [Wireless Router] How to set up IPTV on ASUS router? | Official Support | ASUS Global | H16: NA | J16: NA | L16: NA | N16: Yes | O16: [Wireless Router] How to set up IPTV on ASUS router? | Official Support | ASUS Global | P16: Yes | Q16: [Wireless Router] How to set up IPTV on ASUS router? | Official Support | ASUS Global

Sheet AUM-1-1.ACM
A1: [E.Info.AUM-1-1.ACM](Network Interface) | D1: Required information | P1: [E.Info.DT.ACM-1-1] (Conceptual)
A2: Asset ID | B2: Asset name | C2: Description | D2: [E.Info.AUM-1-1.ACM.NetworkInterface] | F2: [E.Info.AUM-1-1.ACM.ManagedAccessNetworkAsset] | H2: [E.Info.AUM-1-1.ACM.ManagedAccessSecurityAsset] | J2: [E.Info.AUM-1-1.ACM.IntendedFunctionality] (Conditional) | L2: [E.Info.AUM-1-1.ACM.AuthorizedEntity] (Conditional) | N2: [E.Info.AUM-1-1.ACM.AuthenticationMechanism] (Conditional) | P2: DT.AUM-1-1.DN-1 | R2: DT.AUM-1-1.DN-2 | T2: DT.AUM-1-1.DN-3
D3: Description of the network interfaces for the managed access | F3: Description of the managed access to network assets via network interfaces | H3: Description of the managed access to security assets via network interfaces | J3: Description of o the unauthenticated accessible network functions or network functions configuration and | L3: Description of the networks and the physical or logical measures in the equipment’s targeted operational environment that limit access to authorized entities; and | N3: Description of the implemented authentication mechanisms. | P3: Is the managed access for network functions or network functions configuration and is the absence of authentication required for the equipment os intended funtionality? | R3: Is the managed access performed over to authorised entities? | T3: Does the managed access use an authentication mechanism?
D4: Does this item exist? | E4: Reference evidence. | F4: Does this item exist? | G4: Reference evidence. | H4: Does this item exist? | I4: Reference evidence. | J4: Does this item exist? | K4: Reference evidence. | L4: Does this item exist? | M4: Reference evidence. | N4: Does this item exist? | O4: Reference evidence. | P4: Decision. | Q4: Reference evidence. | R4: Decision. | S4: Reference evidence. | T4: Decision. | U4: Reference evidence. | V4: SGS Verdict
A5: Interface-01 | B5: Wi-Fi Radio (2.4 & 5GHz) | C5: Follow the overview in Assest List previously | D5: Yes | E5: ASUS Router HW information in QSG | F5: Yes | G5: [Windows 11/10] Connect to a Wi-Fi network | Official Support | ASUS Global | H5: Yes | I5: client with the Wi-Fi password can access the WiFi | J5: Yes | K5: SSID is unauthenticated accessible network functions | L5: NA | N5: Yes | O5: [Wireless Router] How to modify Wireless(WiFi) Name and Password in ASUS Router? | Official Support | ASUS Global | P5: No | R5: No | T5: Yes | U5: [Wireless Router] How to modify Wireless(WiFi) Name and Password in ASUS Router? | Official Support | ASUS Global
A6: Interface-02 | B6: LAN Port | C6: Follow the overview in Assest List previously | D6: No | E6: ASUS Router HW information in QSG | F6: Yes | G6: The QSG indicated that the router is for indoor use only and client connect to LAN port can obtain the IP. | H6: Yes | I6: The QSG indicated that the router is for indoor use only. | J6: Yes | K6: The QSG indicated that the router is for indoor use only. | L6: Yes | M6: The QSG indicated that the router is for indoor use only. | N6: NA | P6: Yes | Q6: The QSG indicated that the router is for indoor use only and client connect to LAN port can obtain the IP.
A7: Interface-03 | B7: WAN Port | C7: Follow the overview in Assest List previously | D7: Yes | E7: ASUS Router HW information in QSG | F7: Yes | G7: [Wireless Router] How to set up ASUS wireless router to access WebGUI/Router App from WAN? | Official Support | ASUS Global | H7: Yes | I7: [Wireless Router] Introduction of Firewall on ASUS router | Official Support | ASUS Global | J7: Yes | K7: WAN port is default enable | L7: NA | N7: Yes | O7: [Wireless Router] How to set up ASUS wireless router to access WebGUI/Router App from WAN? | Official Support | ASUS Global | P7: No | R7: No | T7: Yes | U7: [Wireless Router] How to set up ASUS wireless router to access WebGUI/Router App from WAN? | Official Support | ASUS Global

Sheet AUM-1-2.ACM
A1: [E.Info.AUM-1-2.ACM](User interface) | D1: Required information | R1: [E.Info.DT.AUM-1-2] (Conceptual)
A2: Asset ID | B2: Asset name | C2: Description | D2: [E.Info.AUM-1-2.ACM.UserInterface] | F2: [E.Info.AUM-1-2.ACM.ManagedAccessNetworkAsset] | H2: [E.Info.AUM-1-2.ACM.ManagedAccessSecurityAsset] | J2: [E.Info.AUM-1-2.ACM.IntendedEnvironment] (Conditional) | L2: [E.Info.AUM-1-2.ACM.AuthenticationMechanism] (Conditional) | N2: [E.Info.AUM-1-2.ACM.ReadOnlyFunctionality] (Conditional) | P2: [E.Info.AUM-1-2.ACM.ReadOnlyLegal] (Conditional) | R2: DT.AUM-1-2.DN-1 | T2: DT.AUM-1-2.DN-2 | V2: DT.AUM-1-2.DN-3 | X2: DT.AUM-1-2.DN-4
